Workbook

Sheet Lote I - Total 
A1: DATA DA ESCRITURA | B1: FRAÇÃO | C1: BLOCO | D1: PISO | E1: APART. | F1: nº | G1: ANOMALIAS | H1: EMPRESA | I1: ESTADO entre 01/07/2026 a 07/07/2026 | J1: DATA ENTRADA ANOMALIA | K1: ESTADO | L1: DATA DA VISTORIA | M1: AGENDAM. CORREÇÃO/ DATA ENCOMENDA | N1: DATA de CORREÇÃO_BAIXA | O1: CONTACTO / NOTAS | P1: NÃO INTERVENCIONADO ANTIGUIDADE (DIAS) | Q1: ENCOMENDADO ANTIGUIDADE (DIAS) | R1: EM OBRA ANTIGUIDADE (DIAS) | S1: CORREÇÃO NÃO ACEITE ANTIGUIDADE (DIAS) | T1: A VERIFICAR ANTIGUIDADE (DIAS) | U1: COLUNA 1 | V1: COLUNA 2 | W1: COLUNA 3 | X1: COLUNA 4 | Y1: COLUNA 5 | Z1: COLUNA 6 | AA1: COLUNA 7
A2: 45499 | B2: A | C2: A | D2: -1 | E2: a | F2: 1 | G2: Substituir réguas do piso | H2: AR | K2: REPARADO | L2: 45322 | N2: 45656 | O2: Solange calado - 91 4719646 | P2: =IF(K2="NÃO INTERVENCIONADO",TODAY()-J2,"") | Q2: =IF(K2="ENCOMENDADO",TODAY()-J2,"") | R2: =IF(K2="EM OBRA",TODAY()-J2,"") | S2: =IF(K2="CORREÇÃO NÃO ACEITE",TODAY()-J2,"") | T2: =IF(K2="A VERIFICAR",TODAY()-J2,"")
A3: 45499 | B3: A | C3: A | D3: -1 | E3: a | F3: 2 | G3: Bordas do armário com defeito | H3: AR | K3: REPARADO | L3: 45322 | N3: 45656 | O3: Solange calado - 91 4719646 | P3: =IF(K3="NÃO INTERVENCIONADO",TODAY()-J3,"") | Q3: =IF(K3="ENCOMENDADO",TODAY()-J3,"") | R3: =IF(K3="EM OBRA",TODAY()-J3,"") | S3: =IF(K3="CORREÇÃO NÃO ACEITE",TODAY()-J3,"") | T3: =IF(K3="A VERIFICAR",TODAY()-J3,"") | V3: =COUNTIF(S1:S5516, "<=30") -> 0 | W3: =COUNTIF(S1:S5516, ">=31")-COUNTIF(S1:S5516, ">60") -> 0 | X3: =COUNTIF(S1:S5516, ">60") -> 0 | Y3: =SUM(V3:X3) -> 0
A4: 45499 | B4: A | C4: A | D4: -1 | E4: a | F4: 3 | G4: Fixar parte plástica do exaustor | H4: AR | K4: REPARADO | L4: 45322 | N4: 45656 | O4: Solange calado - 91 4719646 | P4: =IF(K4="NÃO INTERVENCIONADO",TODAY()-J4,"") | Q4: =IF(K4="ENCOMENDADO",TODAY()-J4,"") | R4: =IF(K4="EM OBRA",TODAY()-J4,"") | S4: =IF(K4="CORREÇÃO NÃO ACEITE",TODAY()-J4,"") | T4: =IF(K4="A VERIFICAR",TODAY()-J4,"") | V4: Menos de 30 dias | W4: de 31 a 60 dias | X4: mais de 60 dias | Y4: Total
A5: 45499 | B5: A | C5: A | D5: -1 | E5: a | F5: 4 | G5: Tambor da máquina da roupa com ferrugem | H5: Cozimafra | K5: REPARADO | L5: 45322 | N5: 45656 | O5: Solange calado - 91 4719646 | P5: =IF(K5="NÃO INTERVENCIONADO",TODAY()-J5,"") | Q5: =IF(K5="ENCOMENDADO",TODAY()-J5,"") | R5: =IF(K5="EM OBRA",TODAY()-J5,"") | S5: =IF(K5="CORREÇÃO NÃO ACEITE",TODAY()-J5,"") | T5: =IF(K5="A VERIFICAR",TODAY()-J5,"") | V5: ANTIGIDADE - CORREÇÃO NÃO ACEITE
A6: 45499 | B6: A | C6: A | D6: -1 | E6: a | F6: 5 | G6: Porta da máquina da louça riscada | H6: AR | K6: REPARADO | L6: 45322 | N6: 45656 | O6: Solange calado - 91 4719646 | P6: =IF(K6="NÃO INTERVENCIONADO",TODAY()-J6,"") | Q6: =IF(K6="ENCOMENDADO",TODAY()-J6,"") | R6: =IF(K6="EM OBRA",TODAY()-J6,"") | S6: =IF(K6="CORREÇÃO NÃO ACEITE",TODAY()-J6,"") | T6: =IF(K6="A VERIFICAR",TODAY()-J6,"")
A7: 45499 | B7: A | C7: A | D7: -1 | E7: a | F7: 6 | G7: Afinar puxador | H7: Serrialu | K7: REPARADO | L7: 45322 | N7: 45540 | O7: Solange calado - 91 4719646 | P7: =IF(K7="NÃO INTERVENCIONADO",TODAY()-J7,"") | Q7: =IF(K7="ENCOMENDADO",TODAY()-J7,"") | R7: =IF(K7="EM OBRA",TODAY()-J7,"") | S7: =IF(K7="CORREÇÃO NÃO ACEITE",TODAY()-J7,"") | T7: =IF(K7="A VERIFICAR",TODAY()-J7,"") | V7: =COUNTIF(R1:R5524, "<=30") -> 0 | W7: =COUNTIF(R1:R5524, ">=31")-COUNTIF(R1:R5524, ">60") -> 0 | X7: =COUNTIF(R1:R5524, ">60") -> 0 | Y7: =SUM(V7:X7) -> 0
A8: 45499 | B8: A | C8: A | D8: -1 | E8: a | F8: 7 | G8: Afinar portas dos roupeiros | H8: AR | K8: REPARADO | L8: 45322 | N8: 45540 | O8: Solange calado - 91 4719646 | P8: =IF(K8="NÃO INTERVENCIONADO",TODAY()-J8,"") | Q8: =IF(K8="ENCOMENDADO",TODAY()-J8,"") | R8: =IF(K8="EM OBRA",TODAY()-J8,"") | S8: =IF(K8="CORREÇÃO NÃO ACEITE",TODAY()-J8,"") | T8: =IF(K8="A VERIFICAR",TODAY()-J8,"") | V8: Menos de 30 dias | W8: de 31 a 60 dias | X8: mais de 60 dias | Y8: Total
A9: 45499 | B9: A | C9: A | D9: -1 | E9: a | F9: 8 | G9: Pintura na guarnição do roupeiro onde a porta raspa | H9: AR | K9: REPARADO | L9: 45322 | N9: 45540 | O9: Solange calado - 91 4719646 | P9: =IF(K9="NÃO INTERVENCIONADO",TODAY()-J9,"") | Q9: =IF(K9="ENCOMENDADO",TODAY()-J9,"") | R9: =IF(K9="EM OBRA",TODAY()-J9,"") | S9: =IF(K9="CORREÇÃO NÃO ACEITE",TODAY()-J9,"") | T9: =IF(K9="A VERIFICAR",TODAY()-J9,"") | V9: ANTIGIDADE - EM OBRA
A10: 45499 | B10: A | C10: A | D10: -1 | E10: a | F10: 9 | G10: Campainha não funciona- Agendar com a MEO | H10: IEOL/MEO | J10: 45526 | K10: REPARADO | L10: 45322 | N10: 45572 | O10: Solange calado - 91 4719646 | P10: =IF(K10="NÃO INTERVENCIONADO",TODAY()-J10,"") | Q10: =IF(K10="ENCOMENDADO",TODAY()-J10,"") | R10: =IF(K10="EM OBRA",TODAY()-J10,"") | S10: =IF(K10="CORREÇÃO NÃO ACEITE",TODAY()-J10,"") | T10: =IF(K10="A VERIFICAR",TODAY()-J10,"")
A11: 45499 | B11: A | C11: A | D11: -1 | E11: a | F11: 10 | G11: Válvula do Bidé deixa passar água | H11: AR | J11: 45526 | K11: REPARADO | L11: 45322 | N11: 45601 | O11: Solange calado - 91 4719646 | P11: =IF(K11="NÃO INTERVENCIONADO",TODAY()-J11,"") | Q11: =IF(K11="ENCOMENDADO",TODAY()-J11,"") | R11: =IF(K11="EM OBRA",TODAY()-J11,"") | S11: =IF(K11="CORREÇÃO NÃO ACEITE",TODAY()-J11,"") | T11: =IF(K11="A VERIFICAR",TODAY()-J11,"") | V11: =COUNTIF(Q3:Q5531, "<=30") -> 0 | W11: =COUNTIF(Q3:Q5531, ">=31")-COUNTIF(Q3:Q5531, ">60") -> 0 | X11: =COUNTIF(Q3:Q5531, ">60") -> 0 | Y11: =SUM(V11:X11) -> 0
A12: 45499 | B12: A | C12: A | D12: -1 | E12: a | F12: 11 | G12: Moldura do Micro Ondas tem ferrugem | H12: Bosch | J12: 45526 | K12: REPARADO | L12: 45322 | N12: 45645 | O12: Solange calado - 91 4719646 | P12: =IF(K12="NÃO INTERVENCIONADO",TODAY()-J12,"") | Q12: =IF(K12="ENCOMENDADO",TODAY()-J12,"") | R12: =IF(K12="EM OBRA",TODAY()-J12,"") | S12: =IF(K12="CORREÇÃO NÃO ACEITE",TODAY()-J12,"") | T12: =IF(K12="A VERIFICAR",TODAY()-J12,"") | V12: Menos de 30 dias | W12: de 31 a 60 dias | X12: mais de 60 dias | Y12: Total
A13: 45499 | B13: A | C13: A | D13: -1 | E13: a | F13: 12 | G13: Chão da sala tem falhas em algumas lâminas e riscos | H13: Silvas | J13: 45526 | K13: REPARADO | L13: 45322 | N13: 45590 | O13: Solange calado - 91 4719646 | P13: =IF(K13="NÃO INTERVENCIONADO",TODAY()-J13,"") | Q13: =IF(K13="ENCOMENDADO",TODAY()-J13,"") | R13: =IF(K13="EM OBRA",TODAY()-J13,"") | S13: =IF(K13="CORREÇÃO NÃO ACEITE",TODAY()-J13,"") | T13: =IF(K13="A VERIFICAR",TODAY()-J13,"") | V13: ANTIGIDADE - ENCOMENDADO
A14: 45499 | B14: A | C14: A | D14: -1 | E14: a | F14: 13 | G14: Rodapé e moldura da porta da cozinha “estalou” | H14: Valco | J14: 45526 | K14: REPARADO | L14: 45322 | N14: 45594 | O14: Solange calado - 91 4719646 | P14: =IF(K14="NÃO INTERVENCIONADO",TODAY()-J14,"") | Q14: =IF(K14="ENCOMENDADO",TODAY()-J14,"") | R14: =IF(K14="EM OBRA",TODAY()-J14,"") | S14: =IF(K14="CORREÇÃO NÃO ACEITE",TODAY()-J14,"") | T14: =IF(K14="A VERIFICAR",TODAY()-J14,"")
A15: 45499 | B15: A | C15: A | D15: -1 | E15: a | F15: 15 | G15: Retificação/preenchimento das juntas dos azuleijos no wc | H15: AR | J15: 45568 | K15: REPARADO | L15: 45322 | N15: 45594 | O15: Solange calado - 91 4719646 | P15: =IF(K15="NÃO INTERVENCIONADO",TODAY()-J15,"") | Q15: =IF(K15="ENCOMENDADO",TODAY()-J15,"") | R15: =IF(K15="EM OBRA",TODAY()-J15,"") | S15: =IF(K15="CORREÇÃO NÃO ACEITE",TODAY()-J15,"") | T15: =IF(K15="A VERIFICAR",TODAY()-J15,"") | V15: Menos de 30 dias | W15: de 31 a 60 dias | X15: mais de 60 dias | Y15: Total
A16: 45499 | B16: A | C16: A | D16: -1 | E16: a | F16: 16 | G16: Limpeza do apartamento, que foi entregue imundo e até cinza de cigarro tinha em cima da máquina de lavar roupa | H16: AR | J16: 45568 | K16: REPARADO | L16: 45322 | N16: 45594 | O16: Solange calado - 91 4719646 | P16: =IF(K16="NÃO INTERVENCIONADO",TODAY()-J16,"") | Q16: =IF(K16="ENCOMENDADO",TODAY()-J16,"") | R16: =IF(K16="EM OBRA",TODAY()-J16,"") | S16: =IF(K16="CORREÇÃO NÃO ACEITE",TODAY()-J16,"") | T16: =IF(K16="A VERIFICAR",TODAY()-J16,"") | V16: ANTIGIDADE - NÃO INTERVENCIONADO
A17: 45499 | B17: A | C17: A | D17: -1 | E17: a | F17: 17 | G17: Limpeza dos vidros e proteção de alumínio das janelas | H17: AR | J17: 45568 | K17: REPARADO | L17: 45322 | N17: 45594 | O17: Solange calado - 91 4719646 | P17: =IF(K17="NÃO INTERVENCIONADO",TODAY()-J17,"") | Q17: =IF(K17="ENCOMENDADO",TODAY()-J17,"") | R17: =IF(K17="EM OBRA",TODAY()-J17,"") | S17: =IF(K17="CORREÇÃO NÃO ACEITE",TODAY()-J17,"") | T17: =IF(K17="A VERIFICAR",TODAY()-J17,"")
A18: 45499 | B18: A | C18: A | D18: -1 | E18: a | F18: 18 | G18: Bicha mal apertada | H18: AR | J18: 45615 | K18: REPARADO | L18: 45322 | N18: 45615 | O18: Solange calado - 91 4719646 | P18: =IF(K18="NÃO INTERVENCIONADO",TODAY()-J18,"") | Q18: =IF(K18="ENCOMENDADO",TODAY()-J18,"") | R18: =IF(K18="EM OBRA",TODAY()-J18,"") | S18: =IF(K18="CORREÇÃO NÃO ACEITE",TODAY()-J18,"") | T18: =IF(K18="A VERIFICAR",TODAY()-J18,"")
A19: 45499 | B19: A | C19: A | D19: -1 | E19: a | F19: 19 | G19: Pintura da parede atrás da porta da entrada | H19: AR | J19: 45568 | K19: REPARADO | L19: 45322 | N19: 45601 | O19: Solange calado - 91 4719646 | P19: =IF(K19="NÃO INTERVENCIONADO",TODAY()-J19,"") | Q19: =IF(K19="ENCOMENDADO",TODAY()-J19,"") | R19: =IF(K19="EM OBRA",TODAY()-J19,"") | S19: =IF(K19="CORREÇÃO NÃO ACEITE",TODAY()-J19,"") | T19: =IF(K19="A VERIFICAR",TODAY()-J19,"") | V19: =COUNTIF(P15:P5538, "<=30") -> 0 | W19: =COUNTIF(P15:P5538, ">=31")-COUNTIF(P15:P5538, ">60") -> 0 | X19: =COUNTIF(P15:P5538, ">60") -> 1 | Y19: =SUM(V19:X19) -> 1
A20: 45517 | B20: AB | C20: B | D20: -1 | E20: b | F20: 1 | G20: Porta arrecadação com amolgado | H20: Sweet Door | K20: REPARADO | L20: 45481 | N20: 45582 | O20: Tiago Correia - 965579733 | P20: =IF(K20="NÃO INTERVENCIONADO",TODAY()-J20,"") | Q20: =IF(K20="ENCOMENDADO",TODAY()-J20,"") | R20: =IF(K20="EM OBRA",TODAY()-J20,"") | S20: =IF(K20="CORREÇÃO NÃO ACEITE",TODAY()-J20,"") | T20: =IF(K20="A VERIFICAR",TODAY()-J20,"")
A21: 45517 | B21: AB | C21: B | D21: -1 | E21: b | F21: 2 | G21: Melhorar pintura apartamento 2ª mão tinta geral | H21: AR | K21: REPARADO | L21: 45481 | N21: 45656 | O21: Tiago Correia - 965579733 | P21: =IF(K21="NÃO INTERVENCIONADO",TODAY()-J21,"") | Q21: =IF(K21="ENCOMENDADO",TODAY()-J21,"") | R21: =IF(K21="EM OBRA",TODAY()-J21,"") | S21: =IF(K21="CORREÇÃO NÃO ACEITE",TODAY()-J21,"") | T21: =IF(K21="A VERIFICAR",TODAY()-J21,"")
A22: 45517 | B22: AB | C22: B | D22: -1 | E22: b | F22: 3 | G22: Fissura na parede | H22: AR | K22: REPARADO | L22: 45481 | N22: 45656 | O22: Tiago Correia - 965579733 | P22: =IF(K22="NÃO INTERVENCIONADO",TODAY()-J22,"") | Q22: =IF(K22="ENCOMENDADO",TODAY()-J22,"") | R22: =IF(K22="EM OBRA",TODAY()-J22,"") | S22: =IF(K22="CORREÇÃO NÃO ACEITE",TODAY()-J22,"") | T22: =IF(K22="A VERIFICAR",TODAY()-J22,"")
A23: 45517 | B23: AB | C23: B | D23: -1 | E23: b | F23: 4 | G23: Melhorar remate porta /parede/fissura | H23: AR | K23: REPARADO | L23: 45481 | N23: 45656 | O23: Tiago Correia - 965579733 | P23: =IF(K23="NÃO INTERVENCIONADO",TODAY()-J23,"") | Q23: =IF(K23="ENCOMENDADO",TODAY()-J23,"") | R23: =IF(K23="EM OBRA",TODAY()-J23,"") | S23: =IF(K23="CORREÇÃO NÃO ACEITE",TODAY()-J23,"") | T23: =IF(K23="A VERIFICAR",TODAY()-J23,"")
A24: 45517 | B24: AB | C24: B | D24: -1 | E24: b | F24: 5 | G24: Melhorar remate rodape /parede/fissura | H24: AR | K24: REPARADO | L24: 45481 | N24: 45656 | O24: Tiago Correia - 965579733 | P24: =IF(K24="NÃO INTERVENCIONADO",TODAY()-J24,"") | Q24: =IF(K24="ENCOMENDADO",TODAY()-J24,"") | R24: =IF(K24="EM OBRA",TODAY()-J24,"") | S24: =IF(K24="CORREÇÃO NÃO ACEITE",TODAY()-J24,"") | T24: =IF(K24="A VERIFICAR",TODAY()-J24,"")
A25: 45517 | B25: AB | C25: B | D25: -1 | E25: b | F25: 6 | G25: Paredes sujas geral | H25: AR | K25: REPARADO | L25: 45481 | N25: 45656 | O25: Tiago Correia - 965579733 | P25: =IF(K25="NÃO INTERVENCIONADO",TODAY()-J25,"") | Q25: =IF(K25="ENCOMENDADO",TODAY()-J25,"") | R25: =IF(K25="EM OBRA",TODAY()-J25,"") | S25: =IF(K25="CORREÇÃO NÃO ACEITE",TODAY()-J25,"") | T25: =IF(K25="A VERIFICAR",TODAY()-J25,"")
A26: 45517 | B26: AB | C26: B | D26: -1 | E26: b | F26: 7 | G26: Folha porta correr entra parede/batente | H26: Globaldis | K26: REPARADO | L26: 45481 | N26: 45656 | O26: Tiago Correia - 965579733 | P26: =IF(K26="NÃO INTERVENCIONADO",TODAY()-J26,"") | Q26: =IF(K26="ENCOMENDADO",TODAY()-J26,"") | R26: =IF(K26="EM OBRA",TODAY()-J26,"") | S26: =IF(K26="CORREÇÃO NÃO ACEITE",TODAY()-J26,"") | T26: =IF(K26="A VERIFICAR",TODAY()-J26,"")
A27: 45517 | B27: AB | C27: B | D27: -1 | E27: b | F27: 8 | G27: Piso cozinha com juntas desalinhadas /Partidos na peça | H27: AR | K27: REPARADO | L27: 45481 | N27: 45656 | O27: Tiago Correia - 965579733 | P27: =IF(K27="NÃO INTERVENCIONADO",TODAY()-J27,"") | Q27: =IF(K27="ENCOMENDADO",TODAY()-J27,"") | R27: =IF(K27="EM OBRA",TODAY()-J27,"") | S27: =IF(K27="CORREÇÃO NÃO ACEITE",TODAY()-J27,"") | T27: =IF(K27="A VERIFICAR",TODAY()-J27,"")
A28: 45517 | B28: AB | C28: B | D28: -1 | E28: b | F28: 9 | G28: Pedra soleira suja | H28: AR | K28: REPARADO | L28: 45481 | N28: 45656 | O28: Tiago Correia - 965579733 | P28: =IF(K28="NÃO INTERVENCIONADO",TODAY()-J28,"") | Q28: =IF(K28="ENCOMENDADO",TODAY()-J28,"") | R28: =IF(K28="EM OBRA",TODAY()-J28,"") | S28: =IF(K28="CORREÇÃO NÃO ACEITE",TODAY()-J28,"") | T28: =IF(K28="A VERIFICAR",TODAY()-J28,"")
A29: 45517 | B29: AB | C29: B | D29: -1 | E29: b | F29: 10 | G29: Refazer silicone caixa estore/fissura | H29: AR | K29: REPARADO | L29: 45481 | N29: 45656 | O29: Tiago Correia - 965579733 | P29: =IF(K29="NÃO INTERVENCIONADO",TODAY()-J29,"") | Q29: =IF(K29="ENCOMENDADO",TODAY()-J29,"") | R29: =IF(K29="EM OBRA",TODAY()-J29,"") | S29: =IF(K29="CORREÇÃO NÃO ACEITE",TODAY()-J29,"") | T29: =IF(K29="A VERIFICAR",TODAY()-J29,"")
A30: 45517 | B30: AB | C30: B | D30: -1 | E30: b | F30: 11 | G30: Guarda da janela do quarto danificada (substituir ) - 1,03x0,62 | H30: Serrialu | K30: REPARADO | L30: 45481 | N30: 45656 | O30: Tiago Correia - 965579733 | P30: =IF(K30="NÃO INTERVENCIONADO",TODAY()-J30,"") | Q30: =IF(K30="ENCOMENDADO",TODAY()-J30,"") | R30: =IF(K30="EM OBRA",TODAY()-J30,"") | S30: =IF(K30="CORREÇÃO NÃO ACEITE",TODAY()-J30,"") | T30: =IF(K30="A VERIFICAR",TODAY()-J30,"")
A31: 45517 | B31: AB | C31: B | D31: -1 | E31: b | F31: 12 | G31: A janela do WC não abre em condiçóes devido a tampa da caixa de estore | H31: Serrialu | K31: REPARADO | L31: 45481 | N31: 45656 | O31: Tiago Correia - 965579733 | P31: =IF(K31="NÃO INTERVENCIONADO",TODAY()-J31,"") | Q31: =IF(K31="ENCOMENDADO",TODAY()-J31,"") | R31: =IF(K31="EM OBRA",TODAY()-J31,"") | S31: =IF(K31="CORREÇÃO NÃO ACEITE",TODAY()-J31,"") | T31: =IF(K31="A VERIFICAR",TODAY()-J31,"")
... A34: 45517 | B34: AB | C34: B | D34: -1 | E34: b | F34: 16 | G34: Porta de entrada precis de afinação | H34: Sweet Door | K34: REPARADO | L34: 45481 | N34: 45555 | O34: Tiago Correia - 965579733 | P34: =IF(K34="NÃO INTERVENCIONADO",TODAY()-J34,"") | Q34: =IF(K34="ENCOMENDADO",TODAY()-J34,"") | R34: =IF(K34="EM OBRA",TODAY()-J34,"") | S34: =IF(K34="CORREÇÃO NÃO ACEITE",TODAY()-J34,"") | T34: =IF(K34="A VERIFICAR",TODAY()-J34,"")
A35: 45517 | B35: AB | C35: B | D35: -1 | E35: b | F35: 17 | G35: janela da cozinha carece de afinação resultante da dificuldade em fechar a mesma | H35: Serrialu | J35: 45551 | K35: REPARADO | L35: 45481 | N35: 45565 | O35: Tiago Correia - 965579733 | P35: =IF(K35="NÃO INTERVENCIONADO",TODAY()-J35,"") | Q35: =IF(K35="ENCOMENDADO",TODAY()-J35,"") | R35: =IF(K35="EM OBRA",TODAY()-J35,"") | S35: =IF(K35="CORREÇÃO NÃO ACEITE",TODAY()-J35,"") | T35: =IF(K35="A VERIFICAR",TODAY()-J35,"")
A36: 45517 | B36: AB | C36: B | D36: -1 | E36: b | F36: 18 | G36: chapa interior da porta de entrada do imóvel danificada | H36: Sweet Door | J36: 45551 | K36: REPARADO | L36: 45481 | N36: 45565 | O36: Tiago Correia - 965579733 | P36: =IF(K36="NÃO INTERVENCIONADO",TODAY()-J36,"") | Q36: =IF(K36="ENCOMENDADO",TODAY()-J36,"") | R36: =IF(K36="EM OBRA",TODAY()-J36,"") | S36: =IF(K36="CORREÇÃO NÃO ACEITE",TODAY()-J36,"") | T36: =IF(K36="A VERIFICAR",TODAY()-J36,"")
A37: 45517 | B37: AB | C37: B | D37: -1 | E37: b | F37: 19 | G37: Tomada da sala queimada | H37: IEOL | J37: 45551 | K37: REPARADO | L37: 45481 | N37: 45565 | O37: Tiago Correia - 965579733 | P37: =IF(K37="NÃO INTERVENCIONADO",TODAY()-J37,"") | Q37: =IF(K37="ENCOMENDADO",TODAY()-J37,"") | R37: =IF(K37="EM OBRA",TODAY()-J37,"") | S37: =IF(K37="CORREÇÃO NÃO ACEITE",TODAY()-J37,"") | T37: =IF(K37="A VERIFICAR",TODAY()-J37,"")
A38: 45517 | B38: AB | C38: B | D38: -1 | E38: b | F38: 20 | G38: Banheira sem água quente e com pouca pressão na agua fria | H38: AR | J38: 45551 | K38: REPARADO | L38: 45481 | N38: 45565 | O38: Tiago Correia - 965579733 | P38: =IF(K38="NÃO INTERVENCIONADO",TODAY()-J38,"") | Q38: =IF(K38="ENCOMENDADO",TODAY()-J38,"") | R38: =IF(K38="EM OBRA",TODAY()-J38,"") | S38: =IF(K38="CORREÇÃO NÃO ACEITE",TODAY()-J38,"") | T38: =IF(K38="A VERIFICAR",TODAY()-J38,"")
A39: 45517 | B39: AB | C39: B | D39: -1 | E39: b | F39: 21 | G39: Substituir pavimento de uma divisão inteira | H39: Silvas | J39: 45559 | K39: REPARADO | L39: 45481 | N39: 45559 | O39: Tiago Correia - 965579733 | P39: =IF(K39="NÃO INTERVENCIONADO",TODAY()-J39,"") | Q39: =IF(K39="ENCOMENDADO",TODAY()-J39,"") | R39: =IF(K39="EM OBRA",TODAY()-J39,"") | S39: =IF(K39="CORREÇÃO NÃO ACEITE",TODAY()-J39,"") | T39: =IF(K39="A VERIFICAR",TODAY()-J39,"")
A40: 45517 | B40: AB | C40: B | D40: -1 | E40: b | F40: 22 | G40: substituição da porta arrecadação | H40: Sweet Door | J40: 45565 | K40: REPARADO | L40: 45481 | N40: 45582 | O40: Tiago Correia - 965579733 | P40: =IF(K40="NÃO INTERVENCIONADO",TODAY()-J40,"") | Q40: =IF(K40="ENCOMENDADO",TODAY()-J40,"") | R40: =IF(K40="EM OBRA",TODAY()-J40,"") | S40: =IF(K40="CORREÇÃO NÃO ACEITE",TODAY()-J40,"") | T40: =IF(K40="A VERIFICAR",TODAY()-J40,"")
A41: 45517 | B41: AB | C41: B | D41: -1 | E41: b | F41: 23 | G41: substituição da porta do roupeiro | H41: Globaldis | J41: 45565 | K41: REPARADO | L41: 45481 | N41: 45681 | O41: Tiago Correia - 965579733 | P41: =IF(K41="NÃO INTERVENCIONADO",TODAY()-J41,"") | Q41: =IF(K41="ENCOMENDADO",TODAY()-J41,"") | R41: =IF(K41="EM OBRA",TODAY()-J41,"") | S41: =IF(K41="CORREÇÃO NÃO ACEITE",TODAY()-J41,"") | T41: =IF(K41="A VERIFICAR",TODAY()-J41,"")
A42: 45517 | B42: AB | C42: B | D42: -1 | E42: b | F42: 24 | G42: instalação de solução que evite o fecho completo da porta (em cassete) da cozinha. | H42: Globaldis | J42: 45607 | K42: REPARADO | L42: 45481 | N42: 45653 | O42: Tiago Correia - 965579733 | P42: =IF(K42="NÃO INTERVENCIONADO",TODAY()-J42,"") | Q42: =IF(K42="ENCOMENDADO",TODAY()-J42,"") | R42: =IF(K42="EM OBRA",TODAY()-J42,"") | S42: =IF(K42="CORREÇÃO NÃO ACEITE",TODAY()-J42,"") | T42: =IF(K42="A VERIFICAR",TODAY()-J42,"")
...

Sheet Resumo - Lote 1
A1: 06/08 a 13/08
A2: Total de apartamentos com vistoria | B2: Anomalias reparadas | C2: Apartamentos reparados | D2: Anomalias por reparar | E2: Apartamentos com anomalias
A3: 142 | B3: 81 | C3: 13 | D3: 964 | E3: 128
A4: 14/08 a 20/08
A5: Total de apartamentos com vistoria | B5: Anomalias reparadas | C5: Apartamentos reparados | D5: Anomalias por reparar | E5: Apartamentos com anomalias | F5: Apartamentos com novas anomalias | G5: Novas anomalias | H5: Apartamentos de novas vistorias com anomalias | I5: Anomalias das novas vistorias
A6: 153 | B6: 298 | C6: 18 | D6: 932 | E6: 133 | F6: 12 | G6: 38 | H6: 11 | I6: 228
A7: 21/08 a 27/08
A8: Total de apartamentos com vistoria | B8: Anomalias reparadas | C8: Apartamentos reparados | D8: Anomalias por reparar | E8: Apartamentos com anomalias | F8: Apartamentos com novas anomalias | G8: Novas anomalias | H8: Apartamentos de novas vistorias com anomalias | I8: Anomalias das novas vistorias | J8: Apartamentos concluídos
A9: 153 | B9: 147 | C9: 38 | D9: 902 | E9: =+A9-J9 -> 127 | F9: =21-H9 -> 20 | G9: =117-I9 -> 88 | H9: 1 | I9: 29 | J9: 26
A10: 28/08 a 03/09
A11: Total de apartamentos com vistoria | B11: Anomalias reparadas | C11: Apartamentos reparados | D11: Anomalias por reparar | E11: Apartamentos com anomalias | F11: Apartamentos com novas anomalias | G11: Novas anomalias | H11: Apartamentos de novas vistorias com anomalias | I11: Anomalias das novas vistorias | J11: Apartamentos concluídos
A12: 153 | B12: 63 | C12: 29 | D12: 983 | E12: 132 | F12: 13 | G12: 144 | H12: 0 | I12: 0 | J12: 21
A13: 04/09 a 10/09
A14: Total de apartamentos com vistoria | B14: Anomalias reparadas | C14: Apartamentos reparados | D14: Anomalias por reparar | E14: Apartamentos com anomalias | F14: Apartamentos com novas anomalias | G14: Novas anomalias | H14: Apartamentos de novas vistorias com anomalias | I14: Anomalias das novas vistorias | J14: Apartamentos concluídos
A15: 153 | B15: 134 | C15: 31 | D15: 874 | E15: 125 | F15: 3 | G15: 25 | H15: 0 | I15: 0 | J15: 28
A16: 11/09 a 17/09
A17: Total de apartamentos com vistoria | B17: Anomalias reparadas | C17: Apartamentos reparados | D17: Anomalias por reparar | E17: Apartamentos com anomalias | F17: Apartamentos com novas anomalias | G17: Novas anomalias | H17: Apartamentos de novas vistorias com anomalias | I17: Anomalias das novas vistorias | J17: Apartamentos concluídos
A18: 153 | B18: 63 | C18: 13 | D18: 839 | E18: 125 | F18: 9 | G18: 28 | H18: 0 | I18: 0 | J18: 28
A19: 18/09 a 24/09
A20: Total de apartamentos com vistoria | B20: Anomalias reparadas | C20: Apartamentos reparados | D20: Anomalias por reparar | E20: Apartamentos com anomalias | F20: Apartamentos com novas anomalias | G20: Novas anomalias | H20: Apartamentos de novas vistorias com anomalias | I20: Anomalias das novas vistorias | J20: Apartamentos concluídos
A21: 153 | B21: 60 | C21: 16 | D21: 817 | E21: 118 | F21: 17 | G21: 38 | H21: 0 | I21: 0 | J21: 28
A22: 25/09 a 01/10
A23: Total de apartamentos com vistoria | B23: Anomalias reparadas | C23: Apartamentos reparados | D23: Anomalias por reparar | E23: Apartamentos com anomalias | F23: Apartamentos com novas anomalias | G23: Novas anomalias | H23: Apartamentos de novas vistorias com anomalias | I23: Anomalias das novas vistorias | J23: Apartamentos concluídos
A24: 156 | B24: 64 | C24: 31 | D24: 847 | E24: 123 | F24: 15 | G24: 48 | H24: 3 | I24: =41+5 -> 46 | J24: 33
A25: 02/10 a 08/10
A26: Total de apartamentos com vistoria | B26: Anomalias reparadas | C26: Apartamentos reparados | D26: Anomalias por reparar | E26: Apartamentos com anomalias | F26: Apartamentos com novas anomalias | G26: Novas anomalias | H26: Apartamentos de novas vistorias com anomalias | I26: Anomalias das novas vistorias | J26: Apartamentos concluídos
A27: 157 | B27: 101 | C27: 22 | D27: =874-8 -> 866 | E27: 125 | F27: 22 | G27: =120-18 -> 102 | H27: 1 | I27: 18 | J27: 27
A28: 09/10 a 15/10
A29: Total de apartamentos com vistoria | B29: Anomalias reparadas | C29: Apartamentos reparados | D29: Anomalias por reparar | E29: Apartamentos com anomalias | F29: Apartamentos com novas anomalias | G29: Novas anomalias | H29: Apartamentos de novas vistorias com anomalias | I29: Anomalias das novas vistorias | J29: Apartamentos concluídos
A30: 158 | B30: 113 | C30: 27 | D30: =854+45 -> 899 | E30: =131 -> 131 | F30: 31 | G30: 103 | H30: 1 | I30: 45 | J30: 26
A31: 16/10 a 22/10
A32: Total de apartamentos com vistoria | B32: Anomalias reparadas | C32: Apartamentos reparados | D32: Anomalias por reparar | E32: Apartamentos com anomalias | F32: Apartamentos com novas anomalias | G32: Novas anomalias | H32: Apartamentos de novas vistorias com anomalias | I32: Anomalias das novas vistorias | J32: Apartamentos concluídos
A33: 158 | B33: 270 | C33: 36 | D33: =773-8 -> 765 | E33: 123 | F33: 38 | G33: 136 | H33: 0 | I33: 0 | J33: 21
A34: 23/10 a 29/10
A35: Total de apartamentos com vistoria | B35: Anomalias reparadas | C35: Apartamentos reparados | D35: Anomalias por reparar | E35: Apartamentos com anomalias | F35: Apartamentos com novas anomalias | G35: Novas anomalias | H35: Apartamentos de novas vistorias com anomalias | I35: Anomalias das novas vistorias | J35: Apartamentos concluídos
A36: 162 | B36: 147 | C36: 41 | D36: =740+3 -> 743 | E36: 134 | F36: 36 | G36: 125 | H36: 4 | I36: =43-7 -> 36 | J36: 20
A37: 30/10 a 05/11
A38: Total de apartamentos com vistoria | B38: Anomalias reparadas | C38: Apartamentos reparados | D38: Anomalias por reparar | E38: Apartamentos com anomalias | F38: Apartamentos com novas anomalias | G38: Novas anomalias | H38: Apartamentos de novas vistorias com anomalias | I38: Anomalias das novas vistorias | J38: Apartamentos concluídos
A39: 162 | B39: 110 | C39: 33 | D39: 690 | E39: 132 | F39: 18 | G39: 57 | H39: 0 | I39: 0 | J39: 19
A40: 06/11 a 12/11
...

Sheet Detalhe1
A1: Detalhes do Contagem de ANOMALIAS - EMPRESA: AR, DATA ESCRITURA: S/ DATA AE (+)
A3: DATA ESCRITURA | B3: FRAÇÃO | C3: BLOCO | D3: PISO | E3: APART. | F3: nº | G3: ANOMALIAS | H3: EMPRESA | I3: ESTADO entre 12.02.25 a 18.02.25 | J3: DATA ENTRADA ANOMALIA | K3: ESTADO | L3: DATA DA VISTORIA | M3: AGENDAM. CORREÇÃO_ DATA ENCOMENDA | N3: DATA de CORREÇÃO_BAIXA | O3: NOVAS ANOMALIAS DESDE 19/12/2024?
A4: 45523 | B4: BE | C4: B | D4: 4 | E4: e | F4: 39 | G4: • Correção dos acabamentos (massa/ silicone) na casa de banho social, junto à banheira e restantes loiças • Anomalia no armário da cozinha (mal funcionamento do sistema de "bloqueio" da porta do armário superior por cima do microondas) • Racha na parede da entrada, junto à porta do apartamento | H4: AR | J4: 45694 | K4: NÃO INTERVENCIONADO | L4: 45398 | O4: SIM
A5: 45561 | B5: Y | C5: A | D5: 8 | E5: a | F5: 21 | G5: Pintura do painel interior | H5: AR | J5: 45588 | K5: CORREÇÃO NÃO ACEITE | L5: 45315
A6: 45516 | B6: EL | C6: D | D6: 0 | E6: c | F6: 16 | G6: Porta lavanderia não abre toda-ver solução (por conta da bomba de calor) - Climacer: Informamos que todo os eletrodomésticos se encontravam no local aquando da instalação da Bomba de calor e do seu arranque. Após a nossa visita verificou-se que existiram alterações às nossas tubagens, para um posterior abastecimento de água à máquina de lavar roupa. Desta forma, toda e qualquer alteração será executada pela empresa, que fez essa instalação adicional. | H6: AR | K6: NÃO INTERVENCIONADO | L6: 45436 | M6: 45693
A7: 45516 | B7: BK | C7: B | D7: 5 | E7: d | F7: 23 | G7: problema na cobertura que faz com que entre/pingue bastante água para a nossa varanda, mais precisamente na zona da passagem da cozinha/lavandaria para a varanda. | H7: AR | J7: 45579 | K7: NÃO INTERVENCIONADO | L7: 45504
A8: 45579 | B8: B | C8: A | D8: -1 | E8: b | F8: 26 | G8: reparação da caixa de correio do bloco A (-1 B) pois a correspondência com a chuva fica inundada. Tem do lado de fora um grande orifício que deixa entrar a chuva quando é tocada a vento. | H8: AR | J8: 45694 | K8: A VERIFICAR | L8: 45566 | O8: SIM
A9: S/ DATA AI | B9: AI | C9: B | D9: 1 | E9: d | F9: 4 | G9: Torneira do chuveiro está danificada - Trocar | H9: AR | K9: ENCOMENDADO | L9: 45391
A10: 45485 | B10: CN | C10: C | D10: 2 | E10: c | F10: 65 | G10: Tubos cobre e cablagem de ligação à Unidade Exterior mal acomodados e com isolamento danificado/ressequido | Soleira já encomenda para ocultar tubagem | H10: AR | J10: 45586 | K10: NÃO INTERVENCIONADO | L10: 45467
A11: 45491 | B11: BJ | C11: B | D11: 5 | E11: c | F11: 26 | G11: Varanda - tem um furo de berbequim na caixilharia da varanda (lado direito) | H11: AR | J11: 45638 | K11: A VERIFICAR | L11: 45371

Sheet Detalhe2
A1: Detalhes do Contagem de ANOMALIAS - EMPRESA: AM&G, ESTADO: NÃO INTERVENCIONADO, DATA ESCRITURA: S/ DATA AE (+)
A3: DATA ESCRITURA | B3: FRAÇÃO | C3: BLOCO | D3: PISO | E3: APART. | F3: nº | G3: ANOMALIAS | H3: EMPRESA | I3: ESTADO entre 05.03.25 a 11.03.25 | J3: DATA ENTRADA ANOMALIA | K3: ESTADO | L3: DATA DA VISTORIA | M3: AGENDAM. CORREÇÃO_ DATA ENCOMENDA | N3: DATA de CORREÇÃO_BAIXA | O3: NOVAS ANOMALIAS DESDE 19/12/2024?
A4: 45562 | B4: EX | C4: D | D4: 2 | E4: a | F4: 20 | G4: Máquina de lavar e sobretudo o frigorífico têm de ser nivelados para estarem equidistantes e alinhados com as restantes bancadas | H4: AM&G | I4: Novo | J4: 45722 | K4: NÃO INTERVENCIONADO | L4: 45495 | O4: SIM

Sheet MACROS (não alterar)
A1: =+'Resumo - Lote 1'!A165 -> Total de apartamentos com vistoria Nota: 1UN - PRESCINDIU DA VISTORIA (APARTAMENTO JÁ ESTAVA HABITADO) | B1: =COUNTA(A7:A177) -> 171 | F1: =+'Resumo - Lote 1'!B165 -> Anomalias reparadas na semana em apreço | O1: =+'Resumo - Lote 1'!C165 -> Apartamentos intervencionados na semana em apreço | U1: =+'Resumo - Lote 1'!D165 -> Anomalias por reparar | Z1: =+'Resumo - Lote 1'!E165 -> Apartamentos com anomalias | AE1: =+'Resumo - Lote 1'!F165 -> Apartamentos com novas anomalias na semana em apreço | AJ1: =+'Resumo - Lote 1'!G165 -> Novas anomalias na semana em apreço | AT1: =+'Resumo - Lote 1'!J165 -> Apartamentos concluídos | AV1: =176+N("total de 176 apartamentos")-5+N("5 vistorias por efectuar a 13/7/2025")-COUNTA(AT5:AT39) -> 136 | AW1: =+IF(AV1='Resumo - Lote 1'!J166,"ok", "ALARME") -> ALARME | BA1: MACRO EXEMPLO:
O2: DATA de CORREÇÃO_BAIXA | P2: (Itens múltiplos) | U2: FRAÇÃO | V2: (Tudo) | Z2: ESTADO | AA2: (Itens múltiplos) | AE2: ESTADO | AF2: (Tudo) | AT2: ESTADO | AU2: (Itens múltiplos)
AE3: DATA ENTRADA ANOMALIA | AF3: (Itens múltiplos) | AJ3: DATA ENTRADA ANOMALIA | AK3: (Itens múltiplos) | BA3: Rótulos de Linha | BB3: Contagem de ANOMALIAS | BC3: Soma de nº
A4: DATA DA VISTORIA | B4: (Itens múltiplos) | F4: DATA de CORREÇÃO_BAIXA | G4: (Itens múltiplos) | O4: Rótulos de Linha | P4: Contagem de APART. | U4: Rótulos de Linha | V4: Contagem de ANOMALIAS | Z4: Rótulos de Linha | AT4: Rótulos de Linha | BA4: A VERIFICAR | BB4: 30 | BC4: 884
O5: REPARADO | P5: 25 | U5: NÃO INTERVENCIONADO | V5: 8 | Z5: AY | AE5: Rótulos de Linha | AF5: Contagem de ANOMALIAS | AJ5: Rótulos de Linha | AK5: Contagem de ANOMALIAS | AT5: AC | BA5: CONFORME PROJETO | BB5: 115 | BC5: 2412
A6: Rótulos de Linha | F6: Rótulos de Linha | G6: Contagem de ANOMALIAS | O6: AN | P6: 1 | U6: CORREÇÃO NÃO ACEITA | V6: 9 | Z6: AZ | AE6: AW | AF6: 1 | AJ6: CONFORME PROJETO | AK6: 2 | AT6: AR | BA6: CORREÇÃO NÃO ACEITE | BB6: 1 | BC6: 6
A7: A | F7: REPARADO | G7: 25 | O7: BU | P7: 2 | U7: Total Geral | V7: 17 | Z7: BK | AE7: BH | AF7: 2 | AJ7: PROCESSO TERMINADO | AK7: 2 | AT7: AT | BA7: ENCOMENDADO | BB7: 31 | BC7: 832
A8: AB | F8: Total Geral | G8: 25 | O8: BX | P8: 3 | Z8: BP | AE8: BS | AF8: 1 | AJ8: REPARADO | AK8: 12 | AT8: AV | BA8: NÃO INTERVENCIONADO | BB8: 18 | BC8: 558
A9: AC | O9: DA | P9: 1 | Z9: BR | AE9: BX | AF9: 1 | AJ9: A VERIFICAR | AK9: 2 | AT9: AW | BA9: PROCESSO TERMINADO | BB9: 49 | BC9: 1371
A10: AD | O10: DV | P10: 3 | Z10: BS | AE10: DJ | AF10: 1 | AJ10: FORA DA GARANTIA | AK10: 1 | AT10: AY | BA10: REPARADO | BB10: 4564 | BC10: 86364
A11: AF | O11: DZ | P11: 1 | Z11: BX | AE11: EB | AF11: 4 | AJ11: Total Geral | AK11: 19 | AT11: AZ | BA11: (em branco)
A12: AG | F12: {=+'Resumo - Lote 1'!I163:J163} -> Semana em análise: | G12: 0 | O12: EB | P12: 7 | Z12: DQ | AE12: EN | AF12: 1 | AT12: BA | BA12: Total Geral | BB12: 4808 | BC12: 92427
A13: AH | F13: =+'Resumo - Lote 1'!I164 -> 46204 | G13: =+'Resumo - Lote 1'!J164 -> 46210 | O13: EC | P13: 2 | Z13: EV | AE13: FE | AF13: 1 | AT13: BE
A14: AI | O14: EO | P14: 1 | Z14: FC | AE14: Total Geral | AF14: 12 | AT14: BH
A15: AJ | O15: ER | P15: 1 | Z15: FO | AT15: BI
A16: AK | O16: FM | P16: 1 | Z16: FZ | AT16: BJ
A17: AL | O17: FZ | P17: 1 | Z17: GA | AT17: BK
A18: AM | O18: H | P18: 1 | Z18: Total Geral | AT18: BL
A19: AN | O19: Total Geral | P19: 25 | AT19: BP
A20: AO | AT20: BR
A21: AP | AT21: BS
A22: AQ | AT22: BT
A23: AR | AT23: BW
A24: AS | AT24: BX
A25: AT | AT25: CO
A26: AU | AT26: CQ
A27: AV | AT27: CZ
A28: AW | AT28: DF
A29: AX | AT29: DG
A30: AY | AT30: DO
A31: AZ | AT31: DQ
... A48: BQ | AT48: Total Geral
A49: BS
A50: BT
A51: BU
A52: BV
A53: BW
A54: BY
A55: BZ
A56: C
...
